Workbook

Sheet MAIN
A1: HSE KPI Dashboard | B1: HSE KPI Dashboard | C1: HSE KPI Dashboard | D1: HSE KPI Dashboard | E1: HSE KPI Dashboard | F1: HSE KPI Dashboard | G1: HSE KPI Dashboard | H1: HSE KPI Dashboard | I1: HSE KPI Dashboard | J1: HSE KPI Dashboard | K1: HSE KPI Dashboard | L1: HSE KPI Dashboard | M1: HSE KPI Dashboard | N1: HSE KPI Dashboard | O1: HSE KPI Dashboard | P1: HSE KPI Dashboard | Q1: HSE KPI Dashboard | R1: HSE KPI Dashboard
A2: Use the dropdowns to switch between one year, selected years, all active years, one month, all months, YTD, full-year, or project-to-date. | B2: Use the dropdowns to switch between one year, selected years, all active years, one month, all months, YTD, full-year, or project-to-date. | C2: Use the dropdowns to switch between one year, selected years, all active years, one month, all months, YTD, full-year, or project-to-date. | D2: Use the dropdowns to switch between one year, selected years, all active years, one month, all months, YTD, full-year, or project-to-date. | E2: Use the dropdowns to switch between one year, selected years, all active years, one month, all months, YTD, full-year, or project-to-date. | F2: Use the dropdowns to switch between one year, selected years, all active years, one month, all months, YTD, full-year, or project-to-date. | G2: Use the dropdowns to switch between one year, selected years, all active years, one month, all months, YTD, full-year, or project-to-date. | H2: Use the dropdowns to switch between one year, selected years, all active years, one month, all months, YTD, full-year, or project-to-date. | I2: Use the dropdowns to switch between one year, selected years, all active years, one month, all months, YTD, full-year, or project-to-date. | J2: Use the dropdowns to switch between one year, selected years, all active years, one month, all months, YTD, full-year, or project-to-date. | K2: Use the dropdowns to switch between one year, selected years, all active years, one month, all months, YTD, full-year, or project-to-date. | L2: Use the dropdowns to switch between one year, selected years, all active years, one month, all months, YTD, full-year, or project-to-date. | M2: Use the dropdowns to switch between one year, selected years, all active years, one month, all months, YTD, full-year, or project-to-date. | N2: Use the dropdowns to switch between one year, selected years, all active years, one month, all months, YTD, full-year, or project-to-date. | O2: Use the dropdowns to switch between one year, selected years, all active years, one month, all months, YTD, full-year, or project-to-date. | P2: Use the dropdowns to switch between one year, selected years, all active years, one month, all months, YTD, full-year, or project-to-date. | Q2: Use the dropdowns to switch between one year, selected years, all active years, one month, all months, YTD, full-year, or project-to-date. | R2: Use the dropdowns to switch between one year, selected years, all active years, one month, all months, YTD, full-year, or project-to-date.
A3: Year | B3: 2025 | C3: Month | D3: All | E3: View | F3: YTD | G3: Year Scope | H3: Selected Year | I3: Category | J3: All | K3: Month No. | L3: =IF($D$3="All",12,MATCH($D$3,LISTS!$B$3:$B$14,0)) -> 12 | M3: Period Months | N3: =COUNTIFS(KPI_DATA!$J$2:$J$2281,"No. of Hours Worked [Exposure Hours]",KPI_DATA!$AA$2:$AA$2281,"Yes") -> 12
T4: Status | U4: Count | W4: Month | X4: Hours | Y4: Near Misses | Z4: TRCs | AB4: Month | AC4: Leading Total | AD4: Lagging Total
A5: Total Hours | B5: Total Hours | C5: Total Hours | D5: Kilometres Driven | E5: Kilometres Driven | F5: Kilometres Driven | G5: TRC Count | H5: TRC Count | I5: TRC Count | J5: Near Misses | K5: Near Misses | L5: Near Misses | M5: Status Score | N5: Status Score | O5: Status Score | P5: Targets Covered | Q5: Targets Covered | R5: Targets Covered | T5: Green | U5: =COUNTIFS($H$12:$H$30,T5,$B$12:$B$30,IF($J$3="All","*",$J$3)) -> 7 | W5: Jan | X5: =SUMIFS(KPI_DATA!$L$2:$L$2281,KPI_DATA!$Y$2:$Y$2281,"Yes",KPI_DATA!$E$2:$E$2281,1,KPI_DATA!$J$2:$J$2281,"No. of Hours Worked [Exposure Hours]") -> 0 | Y5: =SUMIFS(KPI_DATA!$L$2:$L$2281,KPI_DATA!$Y$2:$Y$2281,"Yes",KPI_DATA!$E$2:$E$2281,1,KPI_DATA!$J$2:$J$2281,"Number of Near-Misses") -> 0 | Z5: =SUMIFS(KPI_DATA!$L$2:$L$2281,KPI_DATA!$Y$2:$Y$2281,"Yes",KPI_DATA!$E$2:$E$2281,1,KPI_DATA!$J$2:$J$2281,"Number of TRCs (LTI / RWC / MTC / FAT)") -> 0 | AB5: Jan | AC5: =SUMIFS(KPI_DATA!$L$2:$L$2281,KPI_DATA!$Y$2:$Y$2281,"Yes",KPI_DATA!$E$2:$E$2281,1,KPI_DATA!$I$2:$I$2281,"Leading Indicators") -> 0 | AD5: =SUMIFS(KPI_DATA!$L$2:$L$2281,KPI_DATA!$Y$2:$Y$2281,"Yes",KPI_DATA!$E$2:$E$2281,1,KPI_DATA!$I$2:$I$2281,"Lagging Indicators") -> 0
A6: =SUMIFS(KPI_DATA!$L$2:$L$2281,KPI_DATA!$J$2:$J$2281,"No. of Hours Worked [Exposure Hours]",KPI_DATA!$AA$2:$AA$2281,"Yes") -> 39018 | D6: =SUMIFS(KPI_DATA!$L$2:$L$2281,KPI_DATA!$J$2:$J$2281,"No. of Kilometres Driven",KPI_DATA!$AA$2:$AA$2281,"Yes") -> 8000 | G6: =SUMIFS(KPI_DATA!$L$2:$L$2281,KPI_DATA!$J$2:$J$2281,"Number of TRCs (LTI / RWC / MTC / FAT)",KPI_DATA!$AA$2:$AA$2281,"Yes") -> 0 | J6: =SUMIFS(KPI_DATA!$L$2:$L$2281,KPI_DATA!$J$2:$J$2281,"Number of Near-Misses",KPI_DATA!$AA$2:$AA$2281,"Yes") -> 0 | M6: =IFERROR(COUNTIF($H$12:$H$30,"Green")/(COUNTIF($H$12:$H$30,"Green")+COUNTIF($H$12:$H$30,"Amber")+COUNTIF($H$12:$H$30,"Red")),0) -> 0.36842105 | P6: =SUMIFS(KPI_DATA!$W$2:$W$2281,KPI_DATA!$AA$2:$AA$2281,"Yes")&" / "&COUNTIFS(KPI_DATA!$AA$2:$AA$2281,"Yes") -> 228 / 228 | T6: Amber | U6: =COUNTIFS($H$12:$H$30,T6,$B$12:$B$30,IF($J$3="All","*",$J$3)) -> 2 | W6: Feb | X6: =SUMIFS(KPI_DATA!$L$2:$L$2281,KPI_DATA!$Y$2:$Y$2281,"Yes",KPI_DATA!$E$2:$E$2281,2,KPI_DATA!$J$2:$J$2281,"No. of Hours Worked [Exposure Hours]") -> 0 | Y6: =SUMIFS(KPI_DATA!$L$2:$L$2281,KPI_DATA!$Y$2:$Y$2281,"Yes",KPI_DATA!$E$2:$E$2281,2,KPI_DATA!$J$2:$J$2281,"Number of Near-Misses") -> 0 | Z6: =SUMIFS(KPI_DATA!$L$2:$L$2281,KPI_DATA!$Y$2:$Y$2281,"Yes",KPI_DATA!$E$2:$E$2281,2,KPI_DATA!$J$2:$J$2281,"Number of TRCs (LTI / RWC / MTC / FAT)") -> 0 | AB6: Feb | AC6: =SUMIFS(KPI_DATA!$L$2:$L$2281,KPI_DATA!$Y$2:$Y$2281,"Yes",KPI_DATA!$E$2:$E$2281,2,KPI_DATA!$I$2:$I$2281,"Leading Indicators") -> 0 | AD6: =SUMIFS(KPI_DATA!$L$2:$L$2281,KPI_DATA!$Y$2:$Y$2281,"Yes",KPI_DATA!$E$2:$E$2281,2,KPI_DATA!$I$2:$I$2281,"Lagging Indicators") -> 0
A7: ="Period months: "&TEXT($N$3,"0") -> Period months: 12 | D7: ="Year scope: "&$H$3 -> Year scope: Selected Year | G7: ="TRIR "&TEXT(IFERROR(G6*1000000/A6,0),"0.00")&" /1M hrs" -> TRIR 0.00 /1M hrs | J7: ="Rate "&TEXT(IFERROR(J6*1000000/A6,0),"0.00")&" /1M hrs" -> Rate 0.00 /1M hrs | M7: =TEXT(COUNTIF($H$12:$H$30,"Green"),"0")&" Green / "&TEXT(COUNTIF($H$12:$H$30,"Red"),"0")&" Red" -> 7 Green / 10 Red | P7: ="Year entries: "&TEXT(COUNT(KPI_TARGETS!$G$5:$P$23),"0")&" | Defaults: "&TEXT(COUNT(KPI_TARGETS!$F$5:$F$23),"0") -> Year entries: 38 | Defaults: 19 | T7: Red | U7: =COUNTIFS($H$12:$H$30,T7,$B$12:$B$30,IF($J$3="All","*",$J$3)) -> 10 | W7: Mar | X7: =SUMIFS(KPI_DATA!$L$2:$L$2281,KPI_DATA!$Y$2:$Y$2281,"Yes",KPI_DATA!$E$2:$E$2281,3,KPI_DATA!$J$2:$J$2281,"No. of Hours Worked [Exposure Hours]") -> 0 | Y7: =SUMIFS(KPI_DATA!$L$2:$L$2281,KPI_DATA!$Y$2:$Y$2281,"Yes",KPI_DATA!$E$2:$E$2281,3,KPI_DATA!$J$2:$J$2281,"Number of Near-Misses") -> 0 | Z7: =SUMIFS(KPI_DATA!$L$2:$L$2281,KPI_DATA!$Y$2:$Y$2281,"Yes",KPI_DATA!$E$2:$E$2281,3,KPI_DATA!$J$2:$J$2281,"Number of TRCs (LTI / RWC / MTC / FAT)") -> 0 | AB7: Mar | AC7: =SUMIFS(KPI_DATA!$L$2:$L$2281,KPI_DATA!$Y$2:$Y$2281,"Yes",KPI_DATA!$E$2:$E$2281,3,KPI_DATA!$I$2:$I$2281,"Leading Indicators") -> 0 | AD7: =SUMIFS(KPI_DATA!$L$2:$L$2281,KPI_DATA!$Y$2:$Y$2281,"Yes",KPI_DATA!$E$2:$E$2281,3,KPI_DATA!$I$2:$I$2281,"Lagging Indicators") -> 0
T8: Target Needed | U8: =COUNTIFS($H$12:$H$30,T8,$B$12:$B$30,IF($J$3="All","*",$J$3)) -> 0 | W8: Apr | X8: =SUMIFS(KPI_DATA!$L$2:$L$2281,KPI_DATA!$Y$2:$Y$2281,"Yes",KPI_DATA!$E$2:$E$2281,4,KPI_DATA!$J$2:$J$2281,"No. of Hours Worked [Exposure Hours]") -> 0 | Y8: =SUMIFS(KPI_DATA!$L$2:$L$2281,KPI_DATA!$Y$2:$Y$2281,"Yes",KPI_DATA!$E$2:$E$2281,4,KPI_DATA!$J$2:$J$2281,"Number of Near-Misses") -> 0 | Z8: =SUMIFS(KPI_DATA!$L$2:$L$2281,KPI_DATA!$Y$2:$Y$2281,"Yes",KPI_DATA!$E$2:$E$2281,4,KPI_DATA!$J$2:$J$2281,"Number of TRCs (LTI / RWC / MTC / FAT)") -> 0 | AB8: Apr | AC8: =SUMIFS(KPI_DATA!$L$2:$L$2281,KPI_DATA!$Y$2:$Y$2281,"Yes",KPI_DATA!$E$2:$E$2281,4,KPI_DATA!$I$2:$I$2281,"Leading Indicators") -> 0 | AD8: =SUMIFS(KPI_DATA!$L$2:$L$2281,KPI_DATA!$Y$2:$Y$2281,"Yes",KPI_DATA!$E$2:$E$2281,4,KPI_DATA!$I$2:$I$2281,"Lagging Indicators") -> 0
W9: May | X9: =SUMIFS(KPI_DATA!$L$2:$L$2281,KPI_DATA!$Y$2:$Y$2281,"Yes",KPI_DATA!$E$2:$E$2281,5,KPI_DATA!$J$2:$J$2281,"No. of Hours Worked [Exposure Hours]") -> 0 | Y9: =SUMIFS(KPI_DATA!$L$2:$L$2281,KPI_DATA!$Y$2:$Y$2281,"Yes",KPI_DATA!$E$2:$E$2281,5,KPI_DATA!$J$2:$J$2281,"Number of Near-Misses") -> 0 | Z9: =SUMIFS(KPI_DATA!$L$2:$L$2281,KPI_DATA!$Y$2:$Y$2281,"Yes",KPI_DATA!$E$2:$E$2281,5,KPI_DATA!$J$2:$J$2281,"Number of TRCs (LTI / RWC / MTC / FAT)") -> 0 | AB9: May | AC9: =SUMIFS(KPI_DATA!$L$2:$L$2281,KPI_DATA!$Y$2:$Y$2281,"Yes",KPI_DATA!$E$2:$E$2281,5,KPI_DATA!$I$2:$I$2281,"Leading Indicators") -> 0 | AD9: =SUMIFS(KPI_DATA!$L$2:$L$2281,KPI_DATA!$Y$2:$Y$2281,"Yes",KPI_DATA!$E$2:$E$2281,5,KPI_DATA!$I$2:$I$2281,"Lagging Indicators") -> 0
A10: Selected KPI Performance | W10: Jun | X10: =SUMIFS(KPI_DATA!$L$2:$L$2281,KPI_DATA!$Y$2:$Y$2281,"Yes",KPI_DATA!$E$2:$E$2281,6,KPI_DATA!$J$2:$J$2281,"No. of Hours Worked [Exposure Hours]") -> 2119.75 | Y10: =SUMIFS(KPI_DATA!$L$2:$L$2281,KPI_DATA!$Y$2:$Y$2281,"Yes",KPI_DATA!$E$2:$E$2281,6,KPI_DATA!$J$2:$J$2281,"Number of Near-Misses") -> 0 | Z10: =SUMIFS(KPI_DATA!$L$2:$L$2281,KPI_DATA!$Y$2:$Y$2281,"Yes",KPI_DATA!$E$2:$E$2281,6,KPI_DATA!$J$2:$J$2281,"Number of TRCs (LTI / RWC / MTC / FAT)") -> 0 | AB10: Jun | AC10: =SUMIFS(KPI_DATA!$L$2:$L$2281,KPI_DATA!$Y$2:$Y$2281,"Yes",KPI_DATA!$E$2:$E$2281,6,KPI_DATA!$I$2:$I$2281,"Leading Indicators") -> 58 | AD10: =SUMIFS(KPI_DATA!$L$2:$L$2281,KPI_DATA!$Y$2:$Y$2281,"Yes",KPI_DATA!$E$2:$E$2281,6,KPI_DATA!$I$2:$I$2281,"Lagging Indicators") -> 0
A11: No. | B11: Category | C11: KPI | D11: Actual | E11: Period Target | F11: Direction | G11: Achievement % | H11: Status | I11: Favorable Variance | J11: YTD / Scope Total | K11: Project to Date | L11: MoM Change | M11: Rate / 1M Hrs | W11: Jul | X11: =SUMIFS(KPI_DATA!$L$2:$L$2281,KPI_DATA!$Y$2:$Y$2281,"Yes",KPI_DATA!$E$2:$E$2281,7,KPI_DATA!$J$2:$J$2281,"No. of Hours Worked [Exposure Hours]") -> 4827.75 | Y11: =SUMIFS(KPI_DATA!$L$2:$L$2281,KPI_DATA!$Y$2:$Y$2281,"Yes",KPI_DATA!$E$2:$E$2281,7,KPI_DATA!$J$2:$J$2281,"Number of Near-Misses") -> 0 | Z11: =SUMIFS(KPI_DATA!$L$2:$L$2281,KPI_DATA!$Y$2:$Y$2281,"Yes",KPI_DATA!$E$2:$E$2281,7,KPI_DATA!$J$2:$J$2281,"Number of TRCs (LTI / RWC / MTC / FAT)") -> 0 | AB11: Jul | AC11: =SUMIFS(KPI_DATA!$L$2:$L$2281,KPI_DATA!$Y$2:$Y$2281,"Yes",KPI_DATA!$E$2:$E$2281,7,KPI_DATA!$I$2:$I$2281,"Leading Indicators") -> 82 | AD11: =SUMIFS(KPI_DATA!$L$2:$L$2281,KPI_DATA!$Y$2:$Y$2281,"Yes",KPI_DATA!$E$2:$E$2281,7,KPI_DATA!$I$2:$I$2281,"Lagging Indicators") -> 0
A12: 1 | B12: Exposure | C12: Exposure Hours / Vehicles | D12: =IF(OR($J$3="All",$B12=$J$3),SUMIFS(KPI_DATA!$L$2:$L$2281,KPI_DATA!$J$2:$J$2281,"Exposure Hours / Vehicles",KPI_DATA!$AA$2:$AA$2281,"Yes"),"") -> 0 | E12: =IF(OR($J$3="All",$B12=$J$3),IF(SUMIFS(KPI_DATA!$W$2:$W$2281,KPI_DATA!$J$2:$J$2281,$C12,KPI_DATA!$AA$2:$AA$2281,"Yes")=0,"",SUMIFS(KPI_DATA!$M$2:$M$2281,KPI_DATA!$J$2:$J$2281,$C12,KPI_DATA!$AA$2:$AA$2281,"Yes")),"") -> 1248 | F12: =IF(OR($J$3="All",$B12=$J$3),IFERROR(INDEX(KPI_TARGETS!$E$5:$E$23,MATCH($C12,KPI_TARGETS!$C$5:$C$23,0)),"Higher is better"),"") -> Higher is better | G12: =IF($E12="","",IF($F12="Higher is better",IFERROR($D12/$E12,""),IF($D12=0,1,IFERROR($E12/$D12,"")))) -> 0 | H12: =IF(NOT(OR($J$3="All",$B12=$J$3)),"",IF($E12="","Target Needed",IF($F12="Higher is better",IF($D12>=$E12,"Green",IF($D12>=0.8*$E12,"Amber","Red")),IF($E12=0,IF($D12=0,"Green","Red"),IF($D12<=$E12,"Green",IF($D12<=1.25*$E12,"Amber","Red")))))) -> Red | I12: =IF($E12="","",IF($F12="Higher is better",$D12-$E12,$E12-$D12)) -> -1248 | J12: =IF(OR($J$3="All",$B12=$J$3),SUMIFS(KPI_DATA!$L$2:$L$2281,KPI_DATA!$J$2:$J$2281,"Exposure Hours / Vehicles",KPI_DATA!$Y$2:$Y$2281,"Yes",KPI_DATA!$E$2:$E$2281,"<="&$L$3),"") -> 0 | K12: =IF(OR($J$3="All",$B12=$J$3),SUMIFS(KPI_DATA!$L$2:$L$2281,KPI_DATA!$J$2:$J$2281,"Exposure Hours / Vehicles",KPI_DATA!$C$2:$C$2281,"Yes",KPI_DATA!$A$2:$A$2281,"<"&$B$3)+SUMIFS(KPI_DATA!$L$2:$L$2281,KPI_DATA!$J$2:$J$2281,"Exposure Hours / Vehicles",KPI_DATA!$C$2:$C$2281,"Yes",KPI_DATA!$A$2:$A$2281,$B$3,KPI_DATA!$E$2:$E$2281,"<="&$L$3),"") -> 0 | L12: =IF(OR($D$3="All",$H$3<>"Selected Year"),"",SUMIFS(KPI_DATA!$L$2:$L$2281,KPI_DATA!$J$2:$J$2281,"Exposure Hours / Vehicles",KPI_DATA!$A$2:$A$2281,$B$3,KPI_DATA!$E$2:$E$2281,$L$3)-SUMIFS(KPI_DATA!$L$2:$L$2281,KPI_DATA!$J$2:$J$2281,"Exposure Hours / Vehicles",KPI_DATA!$A$2:$A$2281,IF($L$3=1,$B$3-1,$B$3),KPI_DATA!$E$2:$E$2281,IF($L$3=1,12,$L$3-1))) | M12: =IF($B12<>"Lagging Indicators","",IFERROR($D12*1000000/INDEX($D$12:$D$30,MATCH("No. of Hours Worked [Exposure Hours]",$C$12:$C$30,0)),"")) | W12: Aug | X12: =SUMIFS(KPI_DATA!$L$2:$L$2281,KPI_DATA!$Y$2:$Y$2281,"Yes",KPI_DATA!$E$2:$E$2281,8,KPI_DATA!$J$2:$J$2281,"No. of Hours Worked [Exposure Hours]") -> 6904 | Y12: =SUMIFS(KPI_DATA!$L$2:$L$2281,KPI_DATA!$Y$2:$Y$2281,"Yes",KPI_DATA!$E$2:$E$2281,8,KPI_DATA!$J$2:$J$2281,"Number of Near-Misses") -> 0 | Z12: =SUMIFS(KPI_DATA!$L$2:$L$2281,KPI_DATA!$Y$2:$Y$2281,"Yes",KPI_DATA!$E$2:$E$2281,8,KPI_DATA!$J$2:$J$2281,"Number of TRCs (LTI / RWC / MTC / FAT)") -> 0 | AB12: Aug | AC12: =SUMIFS(KPI_DATA!$L$2:$L$2281,KPI_DATA!$Y$2:$Y$2281,"Yes",KPI_DATA!$E$2:$E$2281,8,KPI_DATA!$I$2:$I$2281,"Leading Indicators") -> 97 | AD12: =SUMIFS(KPI_DATA!$L$2:$L$2281,KPI_DATA!$Y$2:$Y$2281,"Yes",KPI_DATA!$E$2:$E$2281,8,KPI_DATA!$I$2:$I$2281,"Lagging Indicators") -> 0
A13: 1.1 | B13: Exposure | C13: No. of Hours Worked [Exposure Hours] | D13: =IF(OR($J$3="All",$B13=$J$3),SUMIFS(KPI_DATA!$L$2:$L$2281,KPI_DATA!$J$2:$J$2281,"No. of Hours Worked [Exposure Hours]",KPI_DATA!$AA$2:$AA$2281,"Yes"),"") -> 39018 | E13: =IF(OR($J$3="All",$B13=$J$3),IF(SUMIFS(KPI_DATA!$W$2:$W$2281,KPI_DATA!$J$2:$J$2281,$C13,KPI_DATA!$AA$2:$AA$2281,"Yes")=0,"",SUMIFS(KPI_DATA!$M$2:$M$2281,KPI_DATA!$J$2:$J$2281,$C13,KPI_DATA!$AA$2:$AA$2281,"Yes")),"") -> 48000 | F13: =IF(OR($J$3="All",$B13=$J$3),IFERROR(INDEX(KPI_TARGETS!$E$5:$E$23,MATCH($C13,KPI_TARGETS!$C$5:$C$23,0)),"Higher is better"),"") -> Higher is better | G13: =IF($E13="","",IF($F13="Higher is better",IFERROR($D13/$E13,""),IF($D13=0,1,IFERROR($E13/$D13,"")))) -> 0.812875 | H13: =IF(NOT(OR($J$3="All",$B13=$J$3)),"",IF($E13="","Target Needed",IF($F13="Higher is better",IF($D13>=$E13,"Green",IF($D13>=0.8*$E13,"Amber","Red")),IF($E13=0,IF($D13=0,"Green","Red"),IF($D13<=$E13,"Green",IF($D13<=1.25*$E13,"Amber","Red")))))) -> Amber | I13: =IF($E13="","",IF($F13="Higher is better",$D13-$E13,$E13-$D13)) -> -8982 | J13: =IF(OR($J$3="All",$B13=$J$3),SUMIFS(KPI_DATA!$L$2:$L$2281,KPI_DATA!$J$2:$J$2281,"No. of Hours Worked [Exposure Hours]",KPI_DATA!$Y$2:$Y$2281,"Yes",KPI_DATA!$E$2:$E$2281,"<="&$L$3),"") -> 39018 | K13: =IF(OR($J$3="All",$B13=$J$3),SUMIFS(KPI_DATA!$L$2:$L$2281,KPI_DATA!$J$2:$J$2281,"No. of Hours Worked [Exposure Hours]",KPI_DATA!$C$2:$C$2281,"Yes",KPI_DATA!$A$2:$A$2281,"<"&$B$3)+SUMIFS(KPI_DATA!$L$2:$L$2281,KPI_DATA!$J$2:$J$2281,"No. of Hours Worked [Exposure Hours]",KPI_DATA!$C$2:$C$2281,"Yes",KPI_DATA!$A$2:$A$2281,$B$3,KPI_DATA!$E$2:$E$2281,"<="&$L$3),"") -> 39018 | L13: =IF(OR($D$3="All",$H$3<>"Selected Year"),"",SUMIFS(KPI_DATA!$L$2:$L$2281,KPI_DATA!$J$2:$J$2281,"No. of Hours Worked [Exposure Hours]",KPI_DATA!$A$2:$A$2281,$B$3,KPI_DATA!$E$2:$E$2281,$L$3)-SUMIFS(KPI_DATA!$L$2:$L$2281,KPI_DATA!$J$2:$J$2281,"No. of Hours Worked [Exposure Hours]",KPI_DATA!$A$2:$A$2281,IF($L$3=1,$B$3-1,$B$3),KPI_DATA!$E$2:$E$2281,IF($L$3=1,12,$L$3-1))) | M13: =IF($B13<>"Lagging Indicators","",IFERROR($D13*1000000/INDEX($D$12:$D$30,MATCH("No. of Hours Worked [Exposure Hours]",$C$12:$C$30,0)),"")) | W13: Sep | X13: =SUMIFS(KPI_DATA!$L$2:$L$2281,KPI_DATA!$Y$2:$Y$2281,"Yes",KPI_DATA!$E$2:$E$2281,9,KPI_DATA!$J$2:$J$2281,"No. of Hours Worked [Exposure Hours]") -> 4880 | Y13: =SUMIFS(KPI_DATA!$L$2:$L$2281,KPI_DATA!$Y$2:$Y$2281,"Yes",KPI_DATA!$E$2:$E$2281,9,KPI_DATA!$J$2:$J$2281,"Number of Near-Misses") -> 0 | Z13: =SUMIFS(KPI_DATA!$L$2:$L$2281,KPI_DATA!$Y$2:$Y$2281,"Yes",KPI_DATA!$E$2:$E$2281,9,KPI_DATA!$J$2:$J$2281,"Number of TRCs (LTI / RWC / MTC / FAT)") -> 0 | AB13: Sep | AC13: =SUMIFS(KPI_DATA!$L$2:$L$2281,KPI_DATA!$Y$2:$Y$2281,"Yes",KPI_DATA!$E$2:$E$2281,9,KPI_DATA!$I$2:$I$2281,"Leading Indicators") -> 84 | AD13: =SUMIFS(KPI_DATA!$L$2:$L$2281,KPI_DATA!$Y$2:$Y$2281,"Yes",KPI_DATA!$E$2:$E$2281,9,KPI_DATA!$I$2:$I$2281,"Lagging Indicators") -> 0
A14: 1.2 | B14: Exposure | C14: No. of Kilometres Driven | D14: =IF(OR($J$3="All",$B14=$J$3),SUMIFS(KPI_DATA!$L$2:$L$2281,KPI_DATA!$J$2:$J$2281,"No. of Kilometres Driven",KPI_DATA!$AA$2:$AA$2281,"Yes"),"") -> 8000 | E14: =IF(OR($J$3="All",$B14=$J$3),IF(SUMIFS(KPI_DATA!$W$2:$W$2281,KPI_DATA!$J$2:$J$2281,$C14,KPI_DATA!$AA$2:$AA$2281,"Yes")=0,"",SUMIFS(KPI_DATA!$M$2:$M$2281,KPI_DATA!$J$2:$J$2281,$C14,KPI_DATA!$AA$2:$AA$2281,"Yes")),"") -> 96000 | F14: =IF(OR($J$3="All",$B14=$J$3),IFERROR(INDEX(KPI_TARGETS!$E$5:$E$23,MATCH($C14,KPI_TARGETS!$C$5:$C$23,0)),"Higher is better"),"") -> Higher is better | G14: =IF($E14="","",IF($F14="Higher is better",IFERROR($D14/$E14,""),IF($D14=0,1,IFERROR($E14/$D14,"")))) -> 0.083333333 | H14: =IF(NOT(OR($J$3="All",$B14=$J$3)),"",IF($E14="","Target Needed",IF($F14="Higher is better",IF($D14>=$E14,"Green",IF($D14>=0.8*$E14,"Amber","Red")),IF($E14=0,IF($D14=0,"Green","Red"),IF($D14<=$E14,"Green",IF($D14<=1.25*$E14,"Amber","Red")))))) -> Red | I14: =IF($E14="","",IF($F14="Higher is better",$D14-$E14,$E14-$D14)) -> -88000 | J14: =IF(OR($J$3="All",$B14=$J$3),SUMIFS(KPI_DATA!$L$2:$L$2281,KPI_DATA!$J$2:$J$2281,"No. of Kilometres Driven",KPI_DATA!$Y$2:$Y$2281,"Yes",KPI_DATA!$E$2:$E$2281,"<="&$L$3),"") -> 8000 | K14: =IF(OR($J$3="All",$B14=$J$3),SUMIFS(KPI_DATA!$L$2:$L$2281,KPI_DATA!$J$2:$J$2281,"No. of Kilometres Driven",KPI_DATA!$C$2:$C$2281,"Yes",KPI_DATA!$A$2:$A$2281,"<"&$B$3)+SUMIFS(KPI_DATA!$L$2:$L$2281,KPI_DATA!$J$2:$J$2281,"No. of Kilometres Driven",KPI_DATA!$C$2:$C$2281,"Yes",KPI_DATA!$A$2:$A$2281,$B$3,KPI_DATA!$E$2:$E$2281,"<="&$L$3),"") -> 8000 | L14: =IF(OR($D$3="All",$H$3<>"Selected Year"),"",SUMIFS(KPI_DATA!$L$2:$L$2281,KPI_DATA!$J$2:$J$2281,"No. of Kilometres Driven",KPI_DATA!$A$2:$A$2281,$B$3,KPI_DATA!$E$2:$E$2281,$L$3)-SUMIFS(KPI_DATA!$L$2:$L$2281,KPI_DATA!$J$2:$J$2281,"No. of Kilometres Driven",KPI_DATA!$A$2:$A$2281,IF($L$3=1,$B$3-1,$B$3),KPI_DATA!$E$2:$E$2281,IF($L$3=1,12,$L$3-1))) | M14: =IF($B14<>"Lagging Indicators","",IFERROR($D14*1000000/INDEX($D$12:$D$30,MATCH("No. of Hours Worked [Exposure Hours]",$C$12:$C$30,0)),"")) | W14: Oct | X14: =SUMIFS(KPI_DATA!$L$2:$L$2281,KPI_DATA!$Y$2:$Y$2281,"Yes",KPI_DATA!$E$2:$E$2281,10,KPI_DATA!$J$2:$J$2281,"No. of Hours Worked [Exposure Hours]") -> 14779.5 | Y14: =SUMIFS(KPI_DATA!$L$2:$L$2281,KPI_DATA!$Y$2:$Y$2281,"Yes",KPI_DATA!$E$2:$E$2281,10,KPI_DATA!$J$2:$J$2281,"Number of Near-Misses") -> 0 | Z14: =SUMIFS(KPI_DATA!$L$2:$L$2281,KPI_DATA!$Y$2:$Y$2281,"Yes",KPI_DATA!$E$2:$E$2281,10,KPI_DATA!$J$2:$J$2281,"Number of TRCs (LTI / RWC / MTC / FAT)") -> 0 | AB14: Oct | AC14: =SUMIFS(KPI_DATA!$L$2:$L$2281,KPI_DATA!$Y$2:$Y$2281,"Yes",KPI_DATA!$E$2:$E$2281,10,KPI_DATA!$I$2:$I$2281,"Leading Indicators") -> 82 | AD14: =SUMIFS(KPI_DATA!$L$2:$L$2281,KPI_DATA!$Y$2:$Y$2281,"Yes",KPI_DATA!$E$2:$E$2281,10,KPI_DATA!$I$2:$I$2281,"Lagging Indicators") -> 0
A15: 2.1 | B15: Lagging Indicators | C15: Incidents / Accidents (Per Occurrence) | D15: =IF(OR($J$3="All",$B15=$J$3),SUMIFS(KPI_DATA!$L$2:$L$2281,KPI_DATA!$J$2:$J$2281,"Incidents / Accidents (Per Occurrence)",KPI_DATA!$AA$2:$AA$2281,"Yes"),"") -> 0 | E15: =IF(OR($J$3="All",$B15=$J$3),IF(SUMIFS(KPI_DATA!$W$2:$W$2281,KPI_DATA!$J$2:$J$2281,$C15,KPI_DATA!$AA$2:$AA$2281,"Yes")=0,"",SUMIFS(KPI_DATA!$M$2:$M$2281,KPI_DATA!$J$2:$J$2281,$C15,KPI_DATA!$AA$2:$AA$2281,"Yes")),"") -> 0 | F15: =IF(OR($J$3="All",$B15=$J$3),IFERROR(INDEX(KPI_TARGETS!$E$5:$E$23,MATCH($C15,KPI_TARGETS!$C$5:$C$23,0)),"Higher is better"),"") -> Lower is better | G15: =IF($E15="","",IF($F15="Higher is better",IFERROR($D15/$E15,""),IF($D15=0,1,IFERROR($E15/$D15,"")))) -> 1 | H15: =IF(NOT(OR($J$3="All",$B15=$J$3)),"",IF($E15="","Target Needed",IF($F15="Higher is better",IF($D15>=$E15,"Green",IF($D15>=0.8*$E15,"Amber","Red")),IF($E15=0,IF($D15=0,"Green","Red"),IF($D15<=$E15,"Green",IF($D15<=1.25*$E15,"Amber","Red")))))) -> Green | I15: =IF($E15="","",IF($F15="Higher is better",$D15-$E15,$E15-$D15)) -> 0 | J15: =IF(OR($J$3="All",$B15=$J$3),SUMIFS(KPI_DATA!$L$2:$L$2281,KPI_DATA!$J$2:$J$2281,"Incidents / Accidents (Per Occurrence)",KPI_DATA!$Y$2:$Y$2281,"Yes",KPI_DATA!$E$2:$E$2281,"<="&$L$3),"") -> 0 | K15: =IF(OR($J$3="All",$B15=$J$3),SUMIFS(KPI_DATA!$L$2:$L$2281,KPI_DATA!$J$2:$J$2281,"Incidents / Accidents (Per Occurrence)",KPI_DATA!$C$2:$C$2281,"Yes",KPI_DATA!$A$2:$A$2281,"<"&$B$3)+SUMIFS(KPI_DATA!$L$2:$L$2281,KPI_DATA!$J$2:$J$2281,"Incidents / Accidents (Per Occurrence)",KPI_DATA!$C$2:$C$2281,"Yes",KPI_DATA!$A$2:$A$2281,$B$3,KPI_DATA!$E$2:$E$2281,"<="&$L$3),"") -> 0 | L15: =IF(OR($D$3="All",$H$3<>"Selected Year"),"",SUMIFS(KPI_DATA!$L$2:$L$2281,KPI_DATA!$J$2:$J$2281,"Incidents / Accidents (Per Occurrence)",KPI_DATA!$A$2:$A$2281,$B$3,KPI_DATA!$E$2:$E$2281,$L$3)-SUMIFS(KPI_DATA!$L$2:$L$2281,KPI_DATA!$J$2:$J$2281,"Incidents / Accidents (Per Occurrence)",KPI_DATA!$A$2:$A$2281,IF($L$3=1,$B$3-1,$B$3),KPI_DATA!$E$2:$E$2281,IF($L$3=1,12,$L$3-1))) | M15: =IF($B15<>"Lagging Indicators","",IFERROR($D15*1000000/INDEX($D$12:$D$30,MATCH("No. of Hours Worked [Exposure Hours]",$C$12:$C$30,0)),"")) -> 0 | W15: Nov | X15: =SUMIFS(KPI_DATA!$L$2:$L$2281,KPI_DATA!$Y$2:$Y$2281,"Yes",KPI_DATA!$E$2:$E$2281,11,KPI_DATA!$J$2:$J$2281,"No. of Hours Worked [Exposure Hours]") -> 5507 | Y15: =SUMIFS(KPI_DATA!$L$2:$L$2281,KPI_DATA!$Y$2:$Y$2281,"Yes",KPI_DATA!$E$2:$E$2281,11,KPI_DATA!$J$2:$J$2281,"Number of Near-Misses") -> 0 | Z15: =SUMIFS(KPI_DATA!$L$2:$L$2281,KPI_DATA!$Y$2:$Y$2281,"Yes",KPI_DATA!$E$2:$E$2281,11,KPI_DATA!$J$2:$J$2281,"Number of TRCs (LTI / RWC / MTC / FAT)") -> 0 | AB15: Nov | AC15: =SUMIFS(KPI_DATA!$L$2:$L$2281,KPI_DATA!$Y$2:$Y$2281,"Yes",KPI_DATA!$E$2:$E$2281,11,KPI_DATA!$I$2:$I$2281,"Leading Indicators") -> 66 | AD15: =SUMIFS(KPI_DATA!$L$2:$L$2281,KPI_DATA!$Y$2:$Y$2281,"Yes",KPI_DATA!$E$2:$E$2281,11,KPI_DATA!$I$2:$I$2281,"Lagging Indicators") -> 0
A16: 2.2 | B16: Lagging Indicators | C16: Number of Near-Misses | D16: =IF(OR($J$3="All",$B16=$J$3),SUMIFS(KPI_DATA!$L$2:$L$2281,KPI_DATA!$J$2:$J$2281,"Number of Near-Misses",KPI_DATA!$AA$2:$AA$2281,"Yes"),"") -> 0 | E16: =IF(OR($J$3="All",$B16=$J$3),IF(SUMIFS(KPI_DATA!$W$2:$W$2281,KPI_DATA!$J$2:$J$2281,$C16,KPI_DATA!$AA$2:$AA$2281,"Yes")=0,"",SUMIFS(KPI_DATA!$M$2:$M$2281,KPI_DATA!$J$2:$J$2281,$C16,KPI_DATA!$AA$2:$AA$2281,"Yes")),"") -> 0 | F16: =IF(OR($J$3="All",$B16=$J$3),IFERROR(INDEX(KPI_TARGETS!$E$5:$E$23,MATCH($C16,KPI_TARGETS!$C$5:$C$23,0)),"Higher is better"),"") -> Higher is better | G16: =IF($E16="","",IF($F16="Higher is better",IFERROR($D16/$E16,""),IF($D16=0,1,IFERROR($E16/$D16,"")))) | H16: =IF(NOT(OR($J$3="All",$B16=$J$3)),"",IF($E16="","Target Needed",IF($F16="Higher is better",IF($D16>=$E16,"Green",IF($D16>=0.8*$E16,"Amber","Red")),IF($E16=0,IF($D16=0,"Green","Red"),IF($D16<=$E16,"Green",IF($D16<=1.25*$E16,"Amber","Red")))))) -> Green | I16: =IF($E16="","",IF($F16="Higher is better",$D16-$E16,$E16-$D16)) -> 0 | J16: =IF(OR($J$3="All",$B16=$J$3),SUMIFS(KPI_DATA!$L$2:$L$2281,KPI_DATA!$J$2:$J$2281,"Number of Near-Misses",KPI_DATA!$Y$2:$Y$2281,"Yes",KPI_DATA!$E$2:$E$2281,"<="&$L$3),"") -> 0 | K16: =IF(OR($J$3="All",$B16=$J$3),SUMIFS(KPI_DATA!$L$2:$L$2281,KPI_DATA!$J$2:$J$2281,"Number of Near-Misses",KPI_DATA!$C$2:$C$2281,"Yes",KPI_DATA!$A$2:$A$2281,"<"&$B$3)+SUMIFS(KPI_DATA!$L$2:$L$2281,KPI_DATA!$J$2:$J$2281,"Number of Near-Misses",KPI_DATA!$C$2:$C$2281,"Yes",KPI_DATA!$A$2:$A$2281,$B$3,KPI_DATA!$E$2:$E$2281,"<="&$L$3),"") -> 0 | L16: =IF(OR($D$3="All",$H$3<>"Selected Year"),"",SUMIFS(KPI_DATA!$L$2:$L$2281,KPI_DATA!$J$2:$J$2281,"Number of Near-Misses",KPI_DATA!$A$2:$A$2281,$B$3,KPI_DATA!$E$2:$E$2281,$L$3)-SUMIFS(KPI_DATA!$L$2:$L$2281,KPI_DATA!$J$2:$J$2281,"Number of Near-Misses",KPI_DATA!$A$2:$A$2281,IF($L$3=1,$B$3-1,$B$3),KPI_DATA!$E$2:$E$2281,IF($L$3=1,12,$L$3-1))) | M16: =IF($B16<>"Lagging Indicators","",IFERROR($D16*1000000/INDEX($D$12:$D$30,MATCH("No. of Hours Worked [Exposure Hours]",$C$12:$C$30,0)),"")) -> 0 | W16: Dec | X16: =SUMIFS(KPI_DATA!$L$2:$L$2281,KPI_DATA!$Y$2:$Y$2281,"Yes",KPI_DATA!$E$2:$E$2281,12,KPI_DATA!$J$2:$J$2281,"No. of Hours Worked [Exposure Hours]") -> 0 | Y16: =SUMIFS(KPI_DATA!$L$2:$L$2281,KPI_DATA!$Y$2:$Y$2281,"Yes",KPI_DATA!$E$2:$E$2281,12,KPI_DATA!$J$2:$J$2281,"Number of Near-Misses") -> 0 | Z16: =SUMIFS(KPI_DATA!$L$2:$L$2281,KPI_DATA!$Y$2:$Y$2281,"Yes",KPI_DATA!$E$2:$E$2281,12,KPI_DATA!$J$2:$J$2281,"Number of TRCs (LTI / RWC / MTC / FAT)") -> 0 | AB16: Dec | AC16: =SUMIFS(KPI_DATA!$L$2:$L$2281,KPI_DATA!$Y$2:$Y$2281,"Yes",KPI_DATA!$E$2:$E$2281,12,KPI_DATA!$I$2:$I$2281,"Leading Indicators") -> 41 | AD16: =SUMIFS(KPI_DATA!$L$2:$L$2281,KPI_DATA!$Y$2:$Y$2281,"Yes",KPI_DATA!$E$2:$E$2281,12,KPI_DATA!$I$2:$I$2281,"Lagging Indicators") -> 0
A17: 2.3 | B17: Lagging Indicators | C17: High Potential Incidents | D17: =IF(OR($J$3="All",$B17=$J$3),SUMIFS(KPI_DATA!$L$2:$L$2281,KPI_DATA!$J$2:$J$2281,"High Potential Incidents",KPI_DATA!$AA$2:$AA$2281,"Yes"),"") -> 0 | E17: =IF(OR($J$3="All",$B17=$J$3),IF(SUMIFS(KPI_DATA!$W$2:$W$2281,KPI_DATA!$J$2:$J$2281,$C17,KPI_DATA!$AA$2:$AA$2281,"Yes")=0,"",SUMIFS(KPI_DATA!$M$2:$M$2281,KPI_DATA!$J$2:$J$2281,$C17,KPI_DATA!$AA$2:$AA$2281,"Yes")),"") -> 0 | F17: =IF(OR($J$3="All",$B17=$J$3),IFERROR(INDEX(KPI_TARGETS!$E$5:$E$23,MATCH($C17,KPI_TARGETS!$C$5:$C$23,0)),"Higher is better"),"") -> Lower is better | G17: =IF($E17="","",IF($F17="Higher is better",IFERROR($D17/$E17,""),IF($D17=0,1,IFERROR($E17/$D17,"")))) -> 1 | H17: =IF(NOT(OR($J$3="All",$B17=$J$3)),"",IF($E17="","Target Needed",IF($F17="Higher is better",IF($D17>=$E17,"Green",IF($D17>=0.8*$E17,"Amber","Red")),IF($E17=0,IF($D17=0,"Green","Red"),IF($D17<=$E17,"Green",IF($D17<=1.25*$E17,"Amber","Red")))))) -> Green | I17: =IF($E17="","",IF($F17="Higher is better",$D17-$E17,$E17-$D17)) -> 0 | J17: =IF(OR($J$3="All",$B17=$J$3),SUMIFS(KPI_DATA!$L$2:$L$2281,KPI_DATA!$J$2:$J$2281,"High Potential Incidents",KPI_DATA!$Y$2:$Y$2281,"Yes",KPI_DATA!$E$2:$E$2281,"<="&$L$3),"") -> 0 | K17: =IF(OR($J$3="All",$B17=$J$3),SUMIFS(KPI_DATA!$L$2:$L$2281,KPI_DATA!$J$2:$J$2281,"High Potential Incidents",KPI_DATA!$C$2:$C$2281,"Yes",KPI_DATA!$A$2:$A$2281,"<"&$B$3)+SUMIFS(KPI_DATA!$L$2:$L$2281,KPI_DATA!$J$2:$J$2281,"High Potential Incidents",KPI_DATA!$C$2:$C$2281,"Yes",KPI_DATA!$A$2:$A$2281,$B$3,KPI_DATA!$E$2:$E$2281,"<="&$L$3),"") -> 0 | L17: =IF(OR($D$3="All",$H$3<>"Selected Year"),"",SUMIFS(KPI_DATA!$L$2:$L$2281,KPI_DATA!$J$2:$J$2281,"High Potential Incidents",KPI_DATA!$A$2:$A$2281,$B$3,KPI_DATA!$E$2:$E$2281,$L$3)-SUMIFS(KPI_DATA!$L$2:$L$2281,KPI_DATA!$J$2:$J$2281,"High Potential Incidents",KPI_DATA!$A$2:$A$2281,IF($L$3=1,$B$3-1,$B$3),KPI_DATA!$E$2:$E$2281,IF($L$3=1,12,$L$3-1))) | M17: =IF($B17<>"Lagging Indicators","",IFERROR($D17*1000000/INDEX($D$12:$D$30,MATCH("No. of Hours Worked [Exposure Hours]",$C$12:$C$30,0)),"")) -> 0
A18: 2.4 | B18: Lagging Indicators | C18: Life Saving Rule (LSR) Violations | D18: =IF(OR($J$3="All",$B18=$J$3),SUMIFS(KPI_DATA!$L$2:$L$2281,KPI_DATA!$J$2:$J$2281,"Life Saving Rule (LSR) Violations",KPI_DATA!$AA$2:$AA$2281,"Yes"),"") -> 0 | E18: =IF(OR($J$3="All",$B18=$J$3),IF(SUMIFS(KPI_DATA!$W$2:$W$2281,KPI_DATA!$J$2:$J$2281,$C18,KPI_DATA!$AA$2:$AA$2281,"Yes")=0,"",SUMIFS(KPI_DATA!$M$2:$M$2281,KPI_DATA!$J$2:$J$2281,$C18,KPI_DATA!$AA$2:$AA$2281,"Yes")),"") -> 0 | F18: =IF(OR($J$3="All",$B18=$J$3),IFERROR(INDEX(KPI_TARGETS!$E$5:$E$23,MATCH($C18,KPI_TARGETS!$C$5:$C$23,0)),"Higher is better"),"") -> Lower is better | G18: =IF($E18="","",IF($F18="Higher is better",IFERROR($D18/$E18,""),IF($D18=0,1,IFERROR($E18/$D18,"")))) -> 1 | H18: =IF(NOT(OR($J$3="All",$B18=$J$3)),"",IF($E18="","Target Needed",IF($F18="Higher is better",IF($D18>=$E18,"Green",IF($D18>=0.8*$E18,"Amber","Red")),IF($E18=0,IF($D18=0,"Green","Red"),IF($D18<=$E18,"Green",IF($D18<=1.25*$E18,"Amber","Red")))))) -> Green | I18: =IF($E18="","",IF($F18="Higher is better",$D18-$E18,$E18-$D18)) -> 0 | J18: =IF(OR($J$3="All",$B18=$J$3),SUMIFS(KPI_DATA!$L$2:$L$2281,KPI_DATA!$J$2:$J$2281,"Life Saving Rule (LSR) Violations",KPI_DATA!$Y$2:$Y$2281,"Yes",KPI_DATA!$E$2:$E$2281,"<="&$L$3),"") -> 0 | K18: =IF(OR($J$3="All",$B18=$J$3),SUMIFS(KPI_DATA!$L$2:$L$2281,KPI_DATA!$J$2:$J$2281,"Life Saving Rule (LSR) Violations",KPI_DATA!$C$2:$C$2281,"Yes",KPI_DATA!$A$2:$A$2281,"<"&$B$3)+SUMIFS(KPI_DATA!$L$2:$L$2281,KPI_DATA!$J$2:$J$2281,"Life Saving Rule (LSR) Violations",KPI_DATA!$C$2:$C$2281,"Yes",KPI_DATA!$A$2:$A$2281,$B$3,KPI_DATA!$E$2:$E$2281,"<="&$L$3),"") -> 0 | L18: =IF(OR($D$3="All",$H$3<>"Selected Year"),"",SUMIFS(KPI_DATA!$L$2:$L$2281,KPI_DATA!$J$2:$J$2281,"Life Saving Rule (LSR) Violations",KPI_DATA!$A$2:$A$2281,$B$3,KPI_DATA!$E$2:$E$2281,$L$3)-SUMIFS(KPI_DATA!$L$2:$L$2281,KPI_DATA!$J$2:$J$2281,"Life Saving Rule (LSR) Violations",KPI_DATA!$A$2:$A$2281,IF($L$3=1,$B$3-1,$B$3),KPI_DATA!$E$2:$E$2281,IF($L$3=1,12,$L$3-1))) | M18: =IF($B18<>"Lagging Indicators","",IFERROR($D18*1000000/INDEX($D$12:$D$30,MATCH("No. of Hours Worked [Exposure Hours]",$C$12:$C$30,0)),"")) -> 0
A19: 2.5 | B19: Lagging Indicators | C19: Number of TRCs (LTI / RWC / MTC / FAT) | D19: =IF(OR($J$3="All",$B19=$J$3),SUMIFS(KPI_DATA!$L$2:$L$2281,KPI_DATA!$J$2:$J$2281,"Number of TRCs (LTI / RWC / MTC / FAT)",KPI_DATA!$AA$2:$AA$2281,"Yes"),"") -> 0 | E19: =IF(OR($J$3="All",$B19=$J$3),IF(SUMIFS(KPI_DATA!$W$2:$W$2281,KPI_DATA!$J$2:$J$2281,$C19,KPI_DATA!$AA$2:$AA$2281,"Yes")=0,"",SUMIFS(KPI_DATA!$M$2:$M$2281,KPI_DATA!$J$2:$J$2281,$C19,KPI_DATA!$AA$2:$AA$2281,"Yes")),"") -> 0 | F19: =IF(OR($J$3="All",$B19=$J$3),IFERROR(INDEX(KPI_TARGETS!$E$5:$E$23,MATCH($C19,KPI_TARGETS!$C$5:$C$23,0)),"Higher is better"),"") -> Lower is better | G19: =IF($E19="","",IF($F19="Higher is better",IFERROR($D19/$E19,""),IF($D19=0,1,IFERROR($E19/$D19,"")))) -> 1 | H19: =IF(NOT(OR($J$3="All",$B19=$J$3)),"",IF($E19="","Target Needed",IF($F19="Higher is better",IF($D19>=$E19,"Green",IF($D19>=0.8*$E19,"Amber","Red")),IF($E19=0,IF($D19=0,"Green","Red"),IF($D19<=$E19,"Green",IF($D19<=1.25*$E19,"Amber","Red")))))) -> Green | I19: =IF($E19="","",IF($F19="Higher is better",$D19-$E19,$E19-$D19)) -> 0 | J19: =IF(OR($J$3="All",$B19=$J$3),SUMIFS(KPI_DATA!$L$2:$L$2281,KPI_DATA!$J$2:$J$2281,"Number of TRCs (LTI / RWC / MTC / FAT)",KPI_DATA!$Y$2:$Y$2281,"Yes",KPI_DATA!$E$2:$E$2281,"<="&$L$3),"") -> 0 | K19: =IF(OR($J$3="All",$B19=$J$3),SUMIFS(KPI_DATA!$L$2:$L$2281,KPI_DATA!$J$2:$J$2281,"Number of TRCs (LTI / RWC / MTC / FAT)",KPI_DATA!$C$2:$C$2281,"Yes",KPI_DATA!$A$2:$A$2281,"<"&$B$3)+SUMIFS(KPI_DATA!$L$2:$L$2281,KPI_DATA!$J$2:$J$2281,"Number of TRCs (LTI / RWC / MTC / FAT)",KPI_DATA!$C$2:$C$2281,"Yes",KPI_DATA!$A$2:$A$2281,$B$3,KPI_DATA!$E$2:$E$2281,"<="&$L$3),"") -> 0 | L19: =IF(OR($D$3="All",$H$3<>"Selected Year"),"",SUMIFS(KPI_DATA!$L$2:$L$2281,KPI_DATA!$J$2:$J$2281,"Number of TRCs (LTI / RWC / MTC / FAT)",KPI_DATA!$A$2:$A$2281,$B$3,KPI_DATA!$E$2:$E$2281,$L$3)-SUMIFS(KPI_DATA!$L$2:$L$2281,KPI_DATA!$J$2:$J$2281,"Number of TRCs (LTI / RWC / MTC / FAT)",KPI_DATA!$A$2:$A$2281,IF($L$3=1,$B$3-1,$B$3),KPI_DATA!$E$2:$E$2281,IF($L$3=1,12,$L$3-1))) | M19: =IF($B19<>"Lagging Indicators","",IFERROR($D19*1000000/INDEX($D$12:$D$30,MATCH("No. of Hours Worked [Exposure Hours]",$C$12:$C$30,0)),"")) -> 0
A20: 2.6 | B20: Lagging Indicators | C20: Severe Motor Vehicle Incidents (MVI) | D20: =IF(OR($J$3="All",$B20=$J$3),SUMIFS(KPI_DATA!$L$2:$L$2281,KPI_DATA!$J$2:$J$2281,"Severe Motor Vehicle Incidents (MVI)",KPI_DATA!$AA$2:$AA$2281,"Yes"),"") -> 0 | E20: =IF(OR($J$3="All",$B20=$J$3),IF(SUMIFS(KPI_DATA!$W$2:$W$2281,KPI_DATA!$J$2:$J$2281,$C20,KPI_DATA!$AA$2:$AA$2281,"Yes")=0,"",SUMIFS(KPI_DATA!$M$2:$M$2281,KPI_DATA!$J$2:$J$2281,$C20,KPI_DATA!$AA$2:$AA$2281,"Yes")),"") -> 0 | F20: =IF(OR($J$3="All",$B20=$J$3),IFERROR(INDEX(KPI_TARGETS!$E$5:$E$23,MATCH($C20,KPI_TARGETS!$C$5:$C$23,0)),"Higher is better"),"") -> Lower is better | G20: =IF($E20="","",IF($F20="Higher is better",IFERROR($D20/$E20,""),IF($D20=0,1,IFERROR($E20/$D20,"")))) -> 1 | H20: =IF(NOT(OR($J$3="All",$B20=$J$3)),"",IF($E20="","Target Needed",IF($F20="Higher is better",IF($D20>=$E20,"Green",IF($D20>=0.8*$E20,"Amber","Red")),IF($E20=0,IF($D20=0,"Green","Red"),IF($D20<=$E20,"Green",IF($D20<=1.25*$E20,"Amber","Red")))))) -> Green | I20: =IF($E20="","",IF($F20="Higher is better",$D20-$E20,$E20-$D20)) -> 0 | J20: =IF(OR($J$3="All",$B20=$J$3),SUMIFS(KPI_DATA!$L$2:$L$2281,KPI_DATA!$J$2:$J$2281,"Severe Motor Vehicle Incidents (MVI)",KPI_DATA!$Y$2:$Y$2281,"Yes",KPI_DATA!$E$2:$E$2281,"<="&$L$3),"") -> 0 | K20: =IF(OR($J$3="All",$B20=$J$3),SUMIFS(KPI_DATA!$L$2:$L$2281,KPI_DATA!$J$2:$J$2281,"Severe Motor Vehicle Incidents (MVI)",KPI_DATA!$C$2:$C$2281,"Yes",KPI_DATA!$A$2:$A$2281,"<"&$B$3)+SUMIFS(KPI_DATA!$L$2:$L$2281,KPI_DATA!$J$2:$J$2281,"Severe Motor Vehicle Incidents (MVI)",KPI_DATA!$C$2:$C$2281,"Yes",KPI_DATA!$A$2:$A$2281,$B$3,KPI_DATA!$E$2:$E$2281,"<="&$L$3),"") -> 0 | L20: =IF(OR($D$3="All",$H$3<>"Selected Year"),"",SUMIFS(KPI_DATA!$L$2:$L$2281,KPI_DATA!$J$2:$J$2281,"Severe Motor Vehicle Incidents (MVI)",KPI_DATA!$A$2:$A$2281,$B$3,KPI_DATA!$E$2:$E$2281,$L$3)-SUMIFS(KPI_DATA!$L$2:$L$2281,KPI_DATA!$J$2:$J$2281,"Severe Motor Vehicle Incidents (MVI)",KPI_DATA!$A$2:$A$2281,IF($L$3=1,$B$3-1,$B$3),KPI_DATA!$E$2:$E$2281,IF($L$3=1,12,$L$3-1))) | M20: =IF($B20<>"Lagging Indicators","",IFERROR($D20*1000000/INDEX($D$12:$D$30,MATCH("No. of Hours Worked [Exposure Hours]",$C$12:$C$30,0)),"")) -> 0
A21: 3.1 | B21: Leading Indicators | C21: Site Observations / Unsafe Acts / Conditions | D21: =IF(OR($J$3="All",$B21=$J$3),SUMIFS(KPI_DATA!$L$2:$L$2281,KPI_DATA!$J$2:$J$2281,"Site Observations / Unsafe Acts / Conditions",KPI_DATA!$AA$2:$AA$2281,"Yes"),"") -> 223 | E21: =IF(OR($J$3="All",$B21=$J$3),IF(SUMIFS(KPI_DATA!$W$2:$W$2281,KPI_DATA!$J$2:$J$2281,$C21,KPI_DATA!$AA$2:$AA$2281,"Yes")=0,"",SUMIFS(KPI_DATA!$M$2:$M$2281,KPI_DATA!$J$2:$J$2281,$C21,KPI_DATA!$AA$2:$AA$2281,"Yes")),"") -> 420 | F21: =IF(OR($J$3="All",$B21=$J$3),IFERROR(INDEX(KPI_TARGETS!$E$5:$E$23,MATCH($C21,KPI_TARGETS!$C$5:$C$23,0)),"Higher is better"),"") -> Higher is better | G21: =IF($E21="","",IF($F21="Higher is better",IFERROR($D21/$E21,""),IF($D21=0,1,IFERROR($E21/$D21,"")))) -> 0.53095238 | H21: =IF(NOT(OR($J$3="All",$B21=$J$3)),"",IF($E21="","Target Needed",IF($F21="Higher is better",IF($D21>=$E21,"Green",IF($D21>=0.8*$E21,"Amber","Red")),IF($E21=0,IF($D21=0,"Green","Red"),IF($D21<=$E21,"Green",IF($D21<=1.25*$E21,"Amber","Red")))))) -> Red | I21: =IF($E21="","",IF($F21="Higher is better",$D21-$E21,$E21-$D21)) -> -197 | J21: =IF(OR($J$3="All",$B21=$J$3),SUMIFS(KPI_DATA!$L$2:$L$2281,KPI_DATA!$J$2:$J$2281,"Site Observations / Unsafe Acts / Conditions",KPI_DATA!$Y$2:$Y$2281,"Yes",KPI_DATA!$E$2:$E$2281,"<="&$L$3),"") -> 223 | K21: =IF(OR($J$3="All",$B21=$J$3),SUMIFS(KPI_DATA!$L$2:$L$2281,KPI_DATA!$J$2:$J$2281,"Site Observations / Unsafe Acts / Conditions",KPI_DATA!$C$2:$C$2281,"Yes",KPI_DATA!$A$2:$A$2281,"<"&$B$3)+SUMIFS(KPI_DATA!$L$2:$L$2281,KPI_DATA!$J$2:$J$2281,"Site Observations / Unsafe Acts / Conditions",KPI_DATA!$C$2:$C$2281,"Yes",KPI_DATA!$A$2:$A$2281,$B$3,KPI_DATA!$E$2:$E$2281,"<="&$L$3),"") -> 223 | L21: =IF(OR($D$3="All",$H$3<>"Selected Year"),"",SUMIFS(KPI_DATA!$L$2:$L$2281,KPI_DATA!$J$2:$J$2281,"Site Observations / Unsafe Acts / Conditions",KPI_DATA!$A$2:$A$2281,$B$3,KPI_DATA!$E$2:$E$2281,$L$3)-SUMIFS(KPI_DATA!$L$2:$L$2281,KPI_DATA!$J$2:$J$2281,"Site Observations / Unsafe Acts / Conditions",KPI_DATA!$A$2:$A$2281,IF($L$3=1,$B$3-1,$B$3),KPI_DATA!$E$2:$E$2281,IF($L$3=1,12,$L$3-1))) | M21: =IF($B21<>"Lagging Indicators","",IFERROR($D21*1000000/INDEX($D$12:$D$30,MATCH("No. of Hours Worked [Exposure Hours]",$C$12:$C$30,0)),""))
A22: 3.2 | B22: Leading Indicators | C22: Site Inspections | D22: =IF(OR($J$3="All",$B22=$J$3),SUMIFS(KPI_DATA!$L$2:$L$2281,KPI_DATA!$J$2:$J$2281,"Site Inspections",KPI_DATA!$AA$2:$AA$2281,"Yes"),"") -> 28 | E22: =IF(OR($J$3="All",$B22=$J$3),IF(SUMIFS(KPI_DATA!$W$2:$W$2281,KPI_DATA!$J$2:$J$2281,$C22,KPI_DATA!$AA$2:$AA$2281,"Yes")=0,"",SUMIFS(KPI_DATA!$M$2:$M$2281,KPI_DATA!$J$2:$J$2281,$C22,KPI_DATA!$AA$2:$AA$2281,"Yes")),"") -> 60 | F22: =IF(OR($J$3="All",$B22=$J$3),IFERROR(INDEX(KPI_TARGETS!$E$5:$E$23,MATCH($C22,KPI_TARGETS!$C$5:$C$23,0)),"Higher is better"),"") -> Higher is better | G22: =IF($E22="","",IF($F22="Higher is better",IFERROR($D22/$E22,""),IF($D22=0,1,IFERROR($E22/$D22,"")))) -> 0.46666667 | H22: =IF(NOT(OR($J$3="All",$B22=$J$3)),"",IF($E22="","Target Needed",IF($F22="Higher is better",IF($D22>=$E22,"Green",IF($D22>=0.8*$E22,"Amber","Red")),IF($E22=0,IF($D22=0,"Green","Red"),IF($D22<=$E22,"Green",IF($D22<=1.25*$E22,"Amber","Red")))))) -> Red | I22: =IF($E22="","",IF($F22="Higher is better",$D22-$E22,$E22-$D22)) -> -32 | J22: =IF(OR($J$3="All",$B22=$J$3),SUMIFS(KPI_DATA!$L$2:$L$2281,KPI_DATA!$J$2:$J$2281,"Site Inspections",KPI_DATA!$Y$2:$Y$2281,"Yes",KPI_DATA!$E$2:$E$2281,"<="&$L$3),"") -> 28 | K22: =IF(OR($J$3="All",$B22=$J$3),SUMIFS(KPI_DATA!$L$2:$L$2281,KPI_DATA!$J$2:$J$2281,"Site Inspections",KPI_DATA!$C$2:$C$2281,"Yes",KPI_DATA!$A$2:$A$2281,"<"&$B$3)+SUMIFS(KPI_DATA!$L$2:$L$2281,KPI_DATA!$J$2:$J$2281,"Site Inspections",KPI_DATA!$C$2:$C$2281,"Yes",KPI_DATA!$A$2:$A$2281,$B$3,KPI_DATA!$E$2:$E$2281,"<="&$L$3),"") -> 28 | L22: =IF(OR($D$3="All",$H$3<>"Selected Year"),"",SUMIFS(KPI_DATA!$L$2:$L$2281,KPI_DATA!$J$2:$J$2281,"Site Inspections",KPI_DATA!$A$2:$A$2281,$B$3,KPI_DATA!$E$2:$E$2281,$L$3)-SUMIFS(KPI_DATA!$L$2:$L$2281,KPI_DATA!$J$2:$J$2281,"Site Inspections",KPI_DATA!$A$2:$A$2281,IF($L$3=1,$B$3-1,$B$3),KPI_DATA!$E$2:$E$2281,IF($L$3=1,12,$L$3-1))) | M22: =IF($B22<>"Lagging Indicators","",IFERROR($D22*1000000/INDEX($D$12:$D$30,MATCH("No. of Hours Worked [Exposure Hours]",$C$12:$C$30,0)),""))
A23: 3.3 | B23: Leading Indicators | C23: Site HSE Meetings | D23: =IF(OR($J$3="All",$B23=$J$3),SUMIFS(KPI_DATA!$L$2:$L$2281,KPI_DATA!$J$2:$J$2281,"Site HSE Meetings",KPI_DATA!$AA$2:$AA$2281,"Yes"),"") -> 28 | E23: =IF(OR($J$3="All",$B23=$J$3),IF(SUMIFS(KPI_DATA!$W$2:$W$2281,KPI_DATA!$J$2:$J$2281,$C23,KPI_DATA!$AA$2:$AA$2281,"Yes")=0,"",SUMIFS(KPI_DATA!$M$2:$M$2281,KPI_DATA!$J$2:$J$2281,$C23,KPI_DATA!$AA$2:$AA$2281,"Yes")),"") -> 48 | F23: =IF(OR($J$3="All",$B23=$J$3),IFERROR(INDEX(KPI_TARGETS!$E$5:$E$23,MATCH($C23,KPI_TARGETS!$C$5:$C$23,0)),"Higher is better"),"") -> Higher is better | G23: =IF($E23="","",IF($F23="Higher is better",IFERROR($D23/$E23,""),IF($D23=0,1,IFERROR($E23/$D23,"")))) -> 0.58333333 | H23: =IF(NOT(OR($J$3="All",$B23=$J$3)),"",IF($E23="","Target Needed",IF($F23="Higher is better",IF($D23>=$E23,"Green",IF($D23>=0.8*$E23,"Amber","Red")),IF($E23=0,IF($D23=0,"Green","Red"),IF($D23<=$E23,"Green",IF($D23<=1.25*$E23,"Amber","Red")))))) -> Red | I23: =IF($E23="","",IF($F23="Higher is better",$D23-$E23,$E23-$D23)) -> -20 | J23: =IF(OR($J$3="All",$B23=$J$3),SUMIFS(KPI_DATA!$L$2:$L$2281,KPI_DATA!$J$2:$J$2281,"Site HSE Meetings",KPI_DATA!$Y$2:$Y$2281,"Yes",KPI_DATA!$E$2:$E$2281,"<="&$L$3),"") -> 28 | K23: =IF(OR($J$3="All",$B23=$J$3),SUMIFS(KPI_DATA!$L$2:$L$2281,KPI_DATA!$J$2:$J$2281,"Site HSE Meetings",KPI_DATA!$C$2:$C$2281,"Yes",KPI_DATA!$A$2:$A$2281,"<"&$B$3)+SUMIFS(KPI_DATA!$L$2:$L$2281,KPI_DATA!$J$2:$J$2281,"Site HSE Meetings",KPI_DATA!$C$2:$C$2281,"Yes",KPI_DATA!$A$2:$A$2281,$B$3,KPI_DATA!$E$2:$E$2281,"<="&$L$3),"") -> 28 | L23: =IF(OR($D$3="All",$H$3<>"Selected Year"),"",SUMIFS(KPI_DATA!$L$2:$L$2281,KPI_DATA!$J$2:$J$2281,"Site HSE Meetings",KPI_DATA!$A$2:$A$2281,$B$3,KPI_DATA!$E$2:$E$2281,$L$3)-SUMIFS(KPI_DATA!$L$2:$L$2281,KPI_DATA!$J$2:$J$2281,"Site HSE Meetings",KPI_DATA!$A$2:$A$2281,IF($L$3=1,$B$3-1,$B$3),KPI_DATA!$E$2:$E$2281,IF($L$3=1,12,$L$3-1))) | M23: =IF($B23<>"Lagging Indicators","",IFERROR($D23*1000000/INDEX($D$12:$D$30,MATCH("No. of Hours Worked [Exposure Hours]",$C$12:$C$30,0)),""))
A24: 3.4 | B24: Leading Indicators | C24: Site Toolbox Talks | D24: =IF(OR($J$3="All",$B24=$J$3),SUMIFS(KPI_DATA!$L$2:$L$2281,KPI_DATA!$J$2:$J$2281,"Site Toolbox Talks",KPI_DATA!$AA$2:$AA$2281,"Yes"),"") -> 140 | E24: =IF(OR($J$3="All",$B24=$J$3),IF(SUMIFS(KPI_DATA!$W$2:$W$2281,KPI_DATA!$J$2:$J$2281,$C24,KPI_DATA!$AA$2:$AA$2281,"Yes")=0,"",SUMIFS(KPI_DATA!$M$2:$M$2281,KPI_DATA!$J$2:$J$2281,$C24,KPI_DATA!$AA$2:$AA$2281,"Yes")),"") -> 144 | F24: =IF(OR($J$3="All",$B24=$J$3),IFERROR(INDEX(KPI_TARGETS!$E$5:$E$23,MATCH($C24,KPI_TARGETS!$C$5:$C$23,0)),"Higher is better"),"") -> Higher is better | G24: =IF($E24="","",IF($F24="Higher is better",IFERROR($D24/$E24,""),IF($D24=0,1,IFERROR($E24/$D24,"")))) -> 0.97222222 | H24: =IF(NOT(OR($J$3="All",$B24=$J$3)),"",IF($E24="","Target Needed",IF($F24="Higher is better",IF($D24>=$E24,"Green",IF($D24>=0.8*$E24,"Amber","Red")),IF($E24=0,IF($D24=0,"Green","Red"),IF($D24<=$E24,"Green",IF($D24<=1.25*$E24,"Amber","Red")))))) -> Amber | I24: =IF($E24="","",IF($F24="Higher is better",$D24-$E24,$E24-$D24)) -> -4 | J24: =IF(OR($J$3="All",$B24=$J$3),SUMIFS(KPI_DATA!$L$2:$L$2281,KPI_DATA!$J$2:$J$2281,"Site Toolbox Talks",KPI_DATA!$Y$2:$Y$2281,"Yes",KPI_DATA!$E$2:$E$2281,"<="&$L$3),"") -> 140 | K24: =IF(OR($J$3="All",$B24=$J$3),SUMIFS(KPI_DATA!$L$2:$L$2281,KPI_DATA!$J$2:$J$2281,"Site Toolbox Talks",KPI_DATA!$C$2:$C$2281,"Yes",KPI_DATA!$A$2:$A$2281,"<"&$B$3)+SUMIFS(KPI_DATA!$L$2:$L$2281,KPI_DATA!$J$2:$J$2281,"Site Toolbox Talks",KPI_DATA!$C$2:$C$2281,"Yes",KPI_DATA!$A$2:$A$2281,$B$3,KPI_DATA!$E$2:$E$2281,"<="&$L$3),"") -> 140 | L24: =IF(OR($D$3="All",$H$3<>"Selected Year"),"",SUMIFS(KPI_DATA!$L$2:$L$2281,KPI_DATA!$J$2:$J$2281,"Site Toolbox Talks",KPI_DATA!$A$2:$A$2281,$B$3,KPI_DATA!$E$2:$E$2281,$L$3)-SUMIFS(KPI_DATA!$L$2:$L$2281,KPI_DATA!$J$2:$J$2281,"Site Toolbox Talks",KPI_DATA!$A$2:$A$2281,IF($L$3=1,$B$3-1,$B$3),KPI_DATA!$E$2:$E$2281,IF($L$3=1,12,$L$3-1))) | M24: =IF($B24<>"Lagging Indicators","",IFERROR($D24*1000000/INDEX($D$12:$D$30,MATCH("No. of Hours Worked [Exposure Hours]",$C$12:$C$30,0)),""))
A25: 3.5 | B25: Leading Indicators | C25: Management Visits / Walk-around | D25: =IF(OR($J$3="All",$B25=$J$3),SUMIFS(KPI_DATA!$L$2:$L$2281,KPI_DATA!$J$2:$J$2281,"Management Visits / Walk-around",KPI_DATA!$AA$2:$AA$2281,"Yes"),"") -> 28 | E25: =IF(OR($J$3="All",$B25=$J$3),IF(SUMIFS(KPI_DATA!$W$2:$W$2281,KPI_DATA!$J$2:$J$2281,$C25,KPI_DATA!$AA$2:$AA$2281,"Yes")=0,"",SUMIFS(KPI_DATA!$M$2:$M$2281,KPI_DATA!$J$2:$J$2281,$C25,KPI_DATA!$AA$2:$AA$2281,"Yes")),"") -> 48 | F25: =IF(OR($J$3="All",$B25=$J$3),IFERROR(INDEX(KPI_TARGETS!$E$5:$E$23,MATCH($C25,KPI_TARGETS!$C$5:$C$23,0)),"Higher is better"),"") -> Higher is better | G25: =IF($E25="","",IF($F25="Higher is better",IFERROR($D25/$E25,""),IF($D25=0,1,IFERROR($E25/$D25,"")))) -> 0.58333333 | H25: =IF(NOT(OR($J$3="All",$B25=$J$3)),"",IF($E25="","Target Needed",IF($F25="Higher is better",IF($D25>=$E25,"Green",IF($D25>=0.8*$E25,"Amber","Red")),IF($E25=0,IF($D25=0,"Green","Red"),IF($D25<=$E25,"Green",IF($D25<=1.25*$E25,"Amber","Red")))))) -> Red | I25: =IF($E25="","",IF($F25="Higher is better",$D25-$E25,$E25-$D25)) -> -20 | J25: =IF(OR($J$3="All",$B25=$J$3),SUMIFS(KPI_DATA!$L$2:$L$2281,KPI_DATA!$J$2:$J$2281,"Management Visits / Walk-around",KPI_DATA!$Y$2:$Y$2281,"Yes",KPI_DATA!$E$2:$E$2281,"<="&$L$3),"") -> 28 | K25: =IF(OR($J$3="All",$B25=$J$3),SUMIFS(KPI_DATA!$L$2:$L$2281,KPI_DATA!$J$2:$J$2281,"Management Visits / Walk-around",KPI_DATA!$C$2:$C$2281,"Yes",KPI_DATA!$A$2:$A$2281,"<"&$B$3)+SUMIFS(KPI_DATA!$L$2:$L$2281,KPI_DATA!$J$2:$J$2281,"Management Visits / Walk-around",KPI_DATA!$C$2:$C$2281,"Yes",KPI_DATA!$A$2:$A$2281,$B$3,KPI_DATA!$E$2:$E$2281,"<="&$L$3),"") -> 28 | L25: =IF(OR($D$3="All",$H$3<>"Selected Year"),"",SUMIFS(KPI_DATA!$L$2:$L$2281,KPI_DATA!$J$2:$J$2281,"Management Visits / Walk-around",KPI_DATA!$A$2:$A$2281,$B$3,KPI_DATA!$E$2:$E$2281,$L$3)-SUMIFS(KPI_DATA!$L$2:$L$2281,KPI_DATA!$J$2:$J$2281,"Management Visits / Walk-around",KPI_DATA!$A$2:$A$2281,IF($L$3=1,$B$3-1,$B$3),KPI_DATA!$E$2:$E$2281,IF($L$3=1,12,$L$3-1))) | M25: =IF($B25<>"Lagging Indicators","",IFERROR($D25*1000000/INDEX($D$12:$D$30,MATCH("No. of Hours Worked [Exposure Hours]",$C$12:$C$30,0)),""))
A26: 3.6 | B26: Leading Indicators | C26: HSE Training (No. and Participants) | D26: =IF(OR($J$3="All",$B26=$J$3),SUMIFS(KPI_DATA!$L$2:$L$2281,KPI_DATA!$J$2:$J$2281,"HSE Training (No. and Participants)",KPI_DATA!$AA$2:$AA$2281,"Yes"),"") -> 56 | E26: =IF(OR($J$3="All",$B26=$J$3),IF(SUMIFS(KPI_DATA!$W$2:$W$2281,KPI_DATA!$J$2:$J$2281,$C26,KPI_DATA!$AA$2:$AA$2281,"Yes")=0,"",SUMIFS(KPI_DATA!$M$2:$M$2281,KPI_DATA!$J$2:$J$2281,$C26,KPI_DATA!$AA$2:$AA$2281,"Yes")),"") -> 192 | F26: =IF(OR($J$3="All",$B26=$J$3),IFERROR(INDEX(KPI_TARGETS!$E$5:$E$23,MATCH($C26,KPI_TARGETS!$C$5:$C$23,0)),"Higher is better"),"") -> Higher is better | G26: =IF($E26="","",IF($F26="Higher is better",IFERROR($D26/$E26,""),IF($D26=0,1,IFERROR($E26/$D26,"")))) -> 0.29166667 | H26: =IF(NOT(OR($J$3="All",$B26=$J$3)),"",IF($E26="","Target Needed",IF($F26="Higher is better",IF($D26>=$E26,"Green",IF($D26>=0.8*$E26,"Amber","Red")),IF($E26=0,IF($D26=0,"Green","Red"),IF($D26<=$E26,"Green",IF($D26<=1.25*$E26,"Amber","Red")))))) -> Red | I26: =IF($E26="","",IF($F26="Higher is better",$D26-$E26,$E26-$D26)) -> -136 | J26: =IF(OR($J$3="All",$B26=$J$3),SUMIFS(KPI_DATA!$L$2:$L$2281,KPI_DATA!$J$2:$J$2281,"HSE Training (No. and Participants)",KPI_DATA!$Y$2:$Y$2281,"Yes",KPI_DATA!$E$2:$E$2281,"<="&$L$3),"") -> 56 | K26: =IF(OR($J$3="All",$B26=$J$3),SUMIFS(KPI_DATA!$L$2:$L$2281,KPI_DATA!$J$2:$J$2281,"HSE Training (No. and Participants)",KPI_DATA!$C$2:$C$2281,"Yes",KPI_DATA!$A$2:$A$2281,"<"&$B$3)+SUMIFS(KPI_DATA!$L$2:$L$2281,KPI_DATA!$J$2:$J$2281,"HSE Training (No. and Participants)",KPI_DATA!$C$2:$C$2281,"Yes",KPI_DATA!$A$2:$A$2281,$B$3,KPI_DATA!$E$2:$E$2281,"<="&$L$3),"") -> 56 | L26: =IF(OR($D$3="All",$H$3<>"Selected Year"),"",SUMIFS(KPI_DATA!$L$2:$L$2281,KPI_DATA!$J$2:$J$2281,"HSE Training (No. and Participants)",KPI_DATA!$A$2:$A$2281,$B$3,KPI_DATA!$E$2:$E$2281,$L$3)-SUMIFS(KPI_DATA!$L$2:$L$2281,KPI_DATA!$J$2:$J$2281,"HSE Training (No. and Participants)",KPI_DATA!$A$2:$A$2281,IF($L$3=1,$B$3-1,$B$3),KPI_DATA!$E$2:$E$2281,IF($L$3=1,12,$L$3-1))) | M26: =IF($B26<>"Lagging Indicators","",IFERROR($D26*1000000/INDEX($D$12:$D$30,MATCH("No. of Hours Worked [Exposure Hours]",$C$12:$C$30,0)),""))
A27: 3.7 | B27: Leading Indicators | C27: Site HSE Reward / Recognition | D27: =IF(OR($J$3="All",$B27=$J$3),SUMIFS(KPI_DATA!$L$2:$L$2281,KPI_DATA!$J$2:$J$2281,"Site HSE Reward / Recognition",KPI_DATA!$AA$2:$AA$2281,"Yes"),"") -> 7 | E27: =IF(OR($J$3="All",$B27=$J$3),IF(SUMIFS(KPI_DATA!$W$2:$W$2281,KPI_DATA!$J$2:$J$2281,$C27,KPI_DATA!$AA$2:$AA$2281,"Yes")=0,"",SUMIFS(KPI_DATA!$M$2:$M$2281,KPI_DATA!$J$2:$J$2281,$C27,KPI_DATA!$AA$2:$AA$2281,"Yes")),"") -> 12 | F27: =IF(OR($J$3="All",$B27=$J$3),IFERROR(INDEX(KPI_TARGETS!$E$5:$E$23,MATCH($C27,KPI_TARGETS!$C$5:$C$23,0)),"Higher is better"),"") -> Higher is better | G27: =IF($E27="","",IF($F27="Higher is better",IFERROR($D27/$E27,""),IF($D27=0,1,IFERROR($E27/$D27,"")))) -> 0.58333333 | H27: =IF(NOT(OR($J$3="All",$B27=$J$3)),"",IF($E27="","Target Needed",IF($F27="Higher is better",IF($D27>=$E27,"Green",IF($D27>=0.8*$E27,"Amber","Red")),IF($E27=0,IF($D27=0,"Green","Red"),IF($D27<=$E27,"Green",IF($D27<=1.25*$E27,"Amber","Red")))))) -> Red | I27: =IF($E27="","",IF($F27="Higher is better",$D27-$E27,$E27-$D27)) -> -5 | J27: =IF(OR($J$3="All",$B27=$J$3),SUMIFS(KPI_DATA!$L$2:$L$2281,KPI_DATA!$J$2:$J$2281,"Site HSE Reward / Recognition",KPI_DATA!$Y$2:$Y$2281,"Yes",KPI_DATA!$E$2:$E$2281,"<="&$L$3),"") -> 7 | K27: =IF(OR($J$3="All",$B27=$J$3),SUMIFS(KPI_DATA!$L$2:$L$2281,KPI_DATA!$J$2:$J$2281,"Site HSE Reward / Recognition",KPI_DATA!$C$2:$C$2281,"Yes",KPI_DATA!$A$2:$A$2281,"<"&$B$3)+SUMIFS(KPI_DATA!$L$2:$L$2281,KPI_DATA!$J$2:$J$2281,"Site HSE Reward / Recognition",KPI_DATA!$C$2:$C$2281,"Yes",KPI_DATA!$A$2:$A$2281,$B$3,KPI_DATA!$E$2:$E$2281,"<="&$L$3),"") -> 7 | L27: =IF(OR($D$3="All",$H$3<>"Selected Year"),"",SUMIFS(KPI_DATA!$L$2:$L$2281,KPI_DATA!$J$2:$J$2281,"Site HSE Reward / Recognition",KPI_DATA!$A$2:$A$2281,$B$3,KPI_DATA!$E$2:$E$2281,$L$3)-SUMIFS(KPI_DATA!$L$2:$L$2281,KPI_DATA!$J$2:$J$2281,"Site HSE Reward / Recognition",KPI_DATA!$A$2:$A$2281,IF($L$3=1,$B$3-1,$B$3),KPI_DATA!$E$2:$E$2281,IF($L$3=1,12,$L$3-1))) | M27: =IF($B27<>"Lagging Indicators","",IFERROR($D27*1000000/INDEX($D$12:$D$30,MATCH("No. of Hours Worked [Exposure Hours]",$C$12:$C$30,0)),""))
A28: 4.1 | B28: Others | C28: Community / Public Complaints Received | D28: =IF(OR($J$3="All",$B28=$J$3),SUMIFS(KPI_DATA!$L$2:$L$2281,KPI_DATA!$J$2:$J$2281,"Community / Public Complaints Received",KPI_DATA!$AA$2:$AA$2281,"Yes"),"") -> 0 | E28: =IF(OR($J$3="All",$B28=$J$3),IF(SUMIFS(KPI_DATA!$W$2:$W$2281,KPI_DATA!$J$2:$J$2281,$C28,KPI_DATA!$AA$2:$AA$2281,"Yes")=0,"",SUMIFS(KPI_DATA!$M$2:$M$2281,KPI_DATA!$J$2:$J$2281,$C28,KPI_DATA!$AA$2:$AA$2281,"Yes")),"") -> 0 | F28: =IF(OR($J$3="All",$B28=$J$3),IFERROR(INDEX(KPI_TARGETS!$E$5:$E$23,MATCH($C28,KPI_TARGETS!$C$5:$C$23,0)),"Higher is better"),"") -> Lower is better | G28: =IF($E28="","",IF($F28="Higher is better",IFERROR($D28/$E28,""),IF($D28=0,1,IFERROR($E28/$D28,"")))) -> 1 | H28: =IF(NOT(OR($J$3="All",$B28=$J$3)),"",IF($E28="","Target Needed",IF($F28="Higher is better",IF($D28>=$E28,"Green",IF($D28>=0.8*$E28,"Amber","Red")),IF($E28=0,IF($D28=0,"Green","Red"),IF($D28<=$E28,"Green",IF($D28<=1.25*$E28,"Amber","Red")))))) -> Green | I28: =IF($E28="","",IF($F28="Higher is better",$D28-$E28,$E28-$D28)) -> 0 | J28: =IF(OR($J$3="All",$B28=$J$3),SUMIFS(KPI_DATA!$L$2:$L$2281,KPI_DATA!$J$2:$J$2281,"Community / Public Complaints Received",KPI_DATA!$Y$2:$Y$2281,"Yes",KPI_DATA!$E$2:$E$2281,"<="&$L$3),"") -> 0 | K28: =IF(OR($J$3="All",$B28=$J$3),SUMIFS(KPI_DATA!$L$2:$L$2281,KPI_DATA!$J$2:$J$2281,"Community / Public Complaints Received",KPI_DATA!$C$2:$C$2281,"Yes",KPI_DATA!$A$2:$A$2281,"<"&$B$3)+SUMIFS(KPI_DATA!$L$2:$L$2281,KPI_DATA!$J$2:$J$2281,"Community / Public Complaints Received",KPI_DATA!$C$2:$C$2281,"Yes",KPI_DATA!$A$2:$A$2281,$B$3,KPI_DATA!$E$2:$E$2281,"<="&$L$3),"") -> 0 | L28: =IF(OR($D$3="All",$H$3<>"Selected Year"),"",SUMIFS(KPI_DATA!$L$2:$L$2281,KPI_DATA!$J$2:$J$2281,"Community / Public Complaints Received",KPI_DATA!$A$2:$A$2281,$B$3,KPI_DATA!$E$2:$E$2281,$L$3)-SUMIFS(KPI_DATA!$L$2:$L$2281,KPI_DATA!$J$2:$J$2281,"Community / Public Complaints Received",KPI_DATA!$A$2:$A$2281,IF($L$3=1,$B$3-1,$B$3),KPI_DATA!$E$2:$E$2281,IF($L$3=1,12,$L$3-1))) | M28: =IF($B28<>"Lagging Indicators","",IFERROR($D28*1000000/INDEX($D$12:$D$30,MATCH("No. of Hours Worked [Exposure Hours]",$C$12:$C$30,0)),""))
A29: 4.2 | B29: Others | C29: Learning from Incidents (LFI) shared | D29: =IF(OR($J$3="All",$B29=$J$3),SUMIFS(KPI_DATA!$L$2:$L$2281,KPI_DATA!$J$2:$J$2281,"Learning from Incidents (LFI) shared",KPI_DATA!$AA$2:$AA$2281,"Yes"),"") -> 7 | E29: =IF(OR($J$3="All",$B29=$J$3),IF(SUMIFS(KPI_DATA!$W$2:$W$2281,KPI_DATA!$J$2:$J$2281,$C29,KPI_DATA!$AA$2:$AA$2281,"Yes")=0,"",SUMIFS(KPI_DATA!$M$2:$M$2281,KPI_DATA!$J$2:$J$2281,$C29,KPI_DATA!$AA$2:$AA$2281,"Yes")),"") -> 12 | F29: =IF(OR($J$3="All",$B29=$J$3),IFERROR(INDEX(KPI_TARGETS!$E$5:$E$23,MATCH($C29,KPI_TARGETS!$C$5:$C$23,0)),"Higher is better"),"") -> Higher is better | G29: =IF($E29="","",IF($F29="Higher is better",IFERROR($D29/$E29,""),IF($D29=0,1,IFERROR($E29/$D29,"")))) -> 0.58333333 | H29: =IF(NOT(OR($J$3="All",$B29=$J$3)),"",IF($E29="","Target Needed",IF($F29="Higher is better",IF($D29>=$E29,"Green",IF($D29>=0.8*$E29,"Amber","Red")),IF($E29=0,IF($D29=0,"Green","Red"),IF($D29<=$E29,"Green",IF($D29<=1.25*$E29,"Amber","Red")))))) -> Red | I29: =IF($E29="","",IF($F29="Higher is better",$D29-$E29,$E29-$D29)) -> -5 | J29: =IF(OR($J$3="All",$B29=$J$3),SUMIFS(KPI_DATA!$L$2:$L$2281,KPI_DATA!$J$2:$J$2281,"Learning from Incidents (LFI) shared",KPI_DATA!$Y$2:$Y$2281,"Yes",KPI_DATA!$E$2:$E$2281,"<="&$L$3),"") -> 7 | K29: =IF(OR($J$3="All",$B29=$J$3),SUMIFS(KPI_DATA!$L$2:$L$2281,KPI_DATA!$J$2:$J$2281,"Learning from Incidents (LFI) shared",KPI_DATA!$C$2:$C$2281,"Yes",KPI_DATA!$A$2:$A$2281,"<"&$B$3)+SUMIFS(KPI_DATA!$L$2:$L$2281,KPI_DATA!$J$2:$J$2281,"Learning from Incidents (LFI) shared",KPI_DATA!$C$2:$C$2281,"Yes",KPI_DATA!$A$2:$A$2281,$B$3,KPI_DATA!$E$2:$E$2281,"<="&$L$3),"") -> 7 | L29: =IF(OR($D$3="All",$H$3<>"Selected Year"),"",SUMIFS(KPI_DATA!$L$2:$L$2281,KPI_DATA!$J$2:$J$2281,"Learning from Incidents (LFI) shared",KPI_DATA!$A$2:$A$2281,$B$3,KPI_DATA!$E$2:$E$2281,$L$3)-SUMIFS(KPI_DATA!$L$2:$L$2281,KPI_DATA!$J$2:$J$2281,"Learning from Incidents (LFI) shared",KPI_DATA!$A$2:$A$2281,IF($L$3=1,$B$3-1,$B$3),KPI_DATA!$E$2:$E$2281,IF($L$3=1,12,$L$3-1))) | M29: =IF($B29<>"Lagging Indicators","",IFERROR($D29*1000000/INDEX($D$12:$D$30,MATCH("No. of Hours Worked [Exposure Hours]",$C$12:$C$30,0)),""))
A30: 4.3 | B30: Others | C30: GCP / AIP and close open actions | D30: =IF(OR($J$3="All",$B30=$J$3),SUMIFS(KPI_DATA!$L$2:$L$2281,KPI_DATA!$J$2:$J$2281,"GCP / AIP and close open actions",KPI_DATA!$AA$2:$AA$2281,"Yes"),"") -> 7 | E30: =IF(OR($J$3="All",$B30=$J$3),IF(SUMIFS(KPI_DATA!$W$2:$W$2281,KPI_DATA!$J$2:$J$2281,$C30,KPI_DATA!$AA$2:$AA$2281,"Yes")=0,"",SUMIFS(KPI_DATA!$M$2:$M$2281,KPI_DATA!$J$2:$J$2281,$C30,KPI_DATA!$AA$2:$AA$2281,"Yes")),"") -> 12 | F30: =IF(OR($J$3="All",$B30=$J$3),IFERROR(INDEX(KPI_TARGETS!$E$5:$E$23,MATCH($C30,KPI_TARGETS!$C$5:$C$23,0)),"Higher is better"),"") -> Higher is better | G30: =IF($E30="","",IF($F30="Higher is better",IFERROR($D30/$E30,""),IF($D30=0,1,IFERROR($E30/$D30,"")))) -> 0.58333333 | H30: =IF(NOT(OR($J$3="All",$B30=$J$3)),"",IF($E30="","Target Needed",IF($F30="Higher is better",IF($D30>=$E30,"Green",IF($D30>=0.8*$E30,"Amber","Red")),IF($E30=0,IF($D30=0,"Green","Red"),IF($D30<=$E30,"Green",IF($D30<=1.25*$E30,"Amber","Red")))))) -> Red | I30: =IF($E30="","",IF($F30="Higher is better",$D30-$E30,$E30-$D30)) -> -5 | J30: =IF(OR($J$3="All",$B30=$J$3),SUMIFS(KPI_DATA!$L$2:$L$2281,KPI_DATA!$J$2:$J$2281,"GCP / AIP and close open actions",KPI_DATA!$Y$2:$Y$2281,"Yes",KPI_DATA!$E$2:$E$2281,"<="&$L$3),"") -> 7 | K30: =IF(OR($J$3="All",$B30=$J$3),SUMIFS(KPI_DATA!$L$2:$L$2281,KPI_DATA!$J$2:$J$2281,"GCP / AIP and close open actions",KPI_DATA!$C$2:$C$2281,"Yes",KPI_DATA!$A$2:$A$2281,"<"&$B$3)+SUMIFS(KPI_DATA!$L$2:$L$2281,KPI_DATA!$J$2:$J$2281,"GCP / AIP and close open actions",KPI_DATA!$C$2:$C$2281,"Yes",KPI_DATA!$A$2:$A$2281,$B$3,KPI_DATA!$E$2:$E$2281,"<="&$L$3),"") -> 7 | L30: =IF(OR($D$3="All",$H$3<>"Selected Year"),"",SUMIFS(KPI_DATA!$L$2:$L$2281,KPI_DATA!$J$2:$J$2281,"GCP / AIP and close open actions",KPI_DATA!$A$2:$A$2281,$B$3,KPI_DATA!$E$2:$E$2281,$L$3)-SUMIFS(KPI_DATA!$L$2:$L$2281,KPI_DATA!$J$2:$J$2281,"GCP / AIP and close open actions",KPI_DATA!$A$2:$A$2281,IF($L$3=1,$B$3-1,$B$3),KPI_DATA!$E$2:$E$2281,IF($L$3=1,12,$L$3-1))) | M30: =IF($B30<>"Lagging Indicators","",IFERROR($D30*1000000/INDEX($D$12:$D$30,MATCH("No. of Hours Worked [Exposure Hours]",$C$12:$C$30,0)),""))
C54: Overall Statistics
C55: Statistic | D55: Value
C56: Scope | D56: =$H$3 -> Selected Year
C57: Period | D57: =$F$3&" / "&$D$3 -> YTD / All
C58: Green KPIs | D58: =COUNTIFS($H$12:$H$30,"Green",$B$12:$B$30,IF($J$3="All","*",$J$3)) -> 7
C59: Amber KPIs | D59: =COUNTIFS($H$12:$H$30,"Amber",$B$12:$B$30,IF($J$3="All","*",$J$3)) -> 2
C60: Red KPIs | D60: =COUNTIFS($H$12:$H$30,"Red",$B$12:$B$30,IF($J$3="All","*",$J$3)) -> 10
C61: Target Needed | D61: =COUNTIFS($H$12:$H$30,"Target Needed",$B$12:$B$30,IF($J$3="All","*",$J$3)) -> 0
C62: Leading Avg Achievement | D62: =IFERROR(AVERAGEIFS($G$12:$G$30,$B$12:$B$30,"Leading Indicators",$G$12:$G$30,">0"),"") -> 0.57307256
C63: TRIR / 1M hrs | D63: =IFERROR(G6*1000000/A6,"") -> 0
...

Sheet DASHBOARD
A1: Project HSE Statistics | B1: Project HSE Statistics | C1: Project HSE Statistics | D1: Project HSE Statistics | E1: Project HSE Statistics | F1: Project HSE Statistics | G1: Project HSE Statistics | H1: Project HSE Statistics | I1: Project HSE Statistics | J1: Project HSE Statistics | K1: Project HSE Statistics | L1: Project HSE Statistics | M1: Project HSE Statistics | N1: Project HSE Statistics | O1: Project HSE Statistics | P1: Project HSE Statistics | Q1: Project HSE Statistics | R1: Project HSE Statistics | S1: Project HSE Statistics | T1: Project HSE Statistics | U1: Project HSE Statistics
A2: Project-wide totals use SETTINGS Start Year and Finish Year. Multi-year charts compare all active years. | B2: Project-wide totals use SETTINGS Start Year and Finish Year. Multi-year charts compare all active years. | C2: Project-wide totals use SETTINGS Start Year and Finish Year. Multi-year charts compare all active years. | D2: Project-wide totals use SETTINGS Start Year and Finish Year. Multi-year charts compare all active years. | E2: Project-wide totals use SETTINGS Start Year and Finish Year. Multi-year charts compare all active years. | F2: Project-wide totals use SETTINGS Start Year and Finish Year. Multi-year charts compare all active years. | G2: Project-wide totals use SETTINGS Start Year and Finish Year. Multi-year charts compare all active years. | H2: Project-wide totals use SETTINGS Start Year and Finish Year. Multi-year charts compare all active years. | I2: Project-wide totals use SETTINGS Start Year and Finish Year. Multi-year charts compare all active years. | J2: Project-wide totals use SETTINGS Start Year and Finish Year. Multi-year charts compare all active years. | K2: Project-wide totals use SETTINGS Start Year and Finish Year. Multi-year charts compare all active years. | L2: Project-wide totals use SETTINGS Start Year and Finish Year. Multi-year charts compare all active years. | M2: Project-wide totals use SETTINGS Start Year and Finish Year. Multi-year charts compare all active years. | N2: Project-wide totals use SETTINGS Start Year and Finish Year. Multi-year charts compare all active years. | O2: Project-wide totals use SETTINGS Start Year and Finish Year. Multi-year charts compare all active years. | P2: Project-wide totals use SETTINGS Start Year and Finish Year. Multi-year charts compare all active years. | Q2: Project-wide totals use SETTINGS Start Year and Finish Year. Multi-year charts compare all active years. | R2: Project-wide totals use SETTINGS Start Year and Finish Year. Multi-year charts compare all active years. | S2: Project-wide totals use SETTINGS Start Year and Finish Year. Multi-year charts compare all active years. | T2: Project-wide totals use SETTINGS Start Year and Finish Year. Multi-year charts compare all active years. | U2: Project-wide totals use SETTINGS Start Year and Finish Year. Multi-year charts compare all active years.
A3: Project Hours | B3: Project Hours | C3: Project Hours | D3: Kilometres Driven | E3: Kilometres Driven | F3: Kilometres Driven | G3: TRC Count | H3: TRC Count | I3: TRC Count | J3: Near Misses | K3: Near Misses | L3: Near Misses | M3: Project TRIR | N3: Project TRIR | O3: Project TRIR | P3: Targets Covered | Q3: Targets Covered | R3: Targets Covered | S3: Months With Hours | T3: Months With Hours | U3: Months With Hours
